#VRML_SIM R2020b utf8
WorldInfo {
  coordinateSystem "NUE"
}
Viewpoint {
  orientation 0.35307443629270036 -0.9172209494800742 -0.18451062915578406 5.281461043987759
  position 2.3558197103153926 1.1630385760374153 2.0512248543057603
}
Robot {
  translation -0.33115943851227125 0.0697205779437724 0.23344133324823624
  rotation 6.191204499819848e-06 0.9999999999352222 -9.551159506556904e-06 1.5988676682619054
  children [
    DEF body Shape {
      appearance PBRAppearance {
        baseColor 0 0 0.9
        metalness 0
      }
      geometry Box {
        size 0.1 0.05 0.2
      }
    }
    HingeJoint {
      jointParameters HingeJointParameters {
        position 818.799863274249
        anchor 0.06 0 0.05
      }
      device [
        RotationalMotor {
          name "wheel1"
        }
      ]
      endPoint Solid {
        translation 0.06 0 0.05
        rotation 0.6424160788516915 -0.6419047092962422 0.4186405687652881 2.348081484169443
        children [
          DEF wheel Shape {
            appearance PBRAppearance {
              metalness 0
            }
            geometry Cylinder {
              height 0.02
              radius 0.04
            }
          }
        ]
        boundingObject USE wheel
        physics DEF physics_ws Physics {
        }
      }
    }
    HingeJoint {
      jointParameters HingeJointParameters {
        position 215.11905707587866
        anchor -0.06 0 0.05
      }
      device [
        RotationalMotor {
          name "wheel2"
        }
      ]
      endPoint Solid {
        translation -0.06 0 0.05
        rotation 0.561625341549597 -0.5611782822204594 0.6079933480667309 2.048333059048638
        children [
          USE wheel
        ]
        name "solid(1)"
        boundingObject USE wheel
        physics USE physics_ws
      }
    }
    HingeJoint {
      jointParameters HingeJointParameters {
        position 818.7999875316966
        anchor 0.06 0 -0.05
      }
      device [
        RotationalMotor {
          name "wheel3"
        }
      ]
      endPoint Solid {
        translation 0.06 0 -0.05
        rotation 0.6424313653909327 -0.641919983667253 0.4185936876382341 2.3481613101014718
        children [
          USE wheel
        ]
        name "solid(2)"
        boundingObject USE wheel
        physics USE physics_ws
      }
    }
    HingeJoint {
      jointParameters HingeJointParameters {
        position 215.1191823618866
        anchor -0.06 0 -0.05
      }
      device [
        RotationalMotor {
          name "wheel4"
        }
      ]
      endPoint Solid {
        translation -0.06 -2.531134062727459e-10 -0.0500000031605609
        rotation 0.5616514338897236 -0.561204353790824 0.6079451785283282 2.0484034244801723
        children [
          USE wheel
        ]
        name "solid(3)"
        boundingObject USE wheel
        physics USE physics_ws
      }
    }
    DistanceSensor {
      translation 0.02 0 0.1
      rotation 0 1 0 -1.27
      children [
        DEF sensor Shape {
          appearance PBRAppearance {
            baseColor 1 0.4 1
          }
          geometry Box {
            size 0.01 0.01 0.01
          }
        }
      ]
      name "ds_left"
      boundingObject USE sensor
      physics Physics {
      }
    }
    DistanceSensor {
      translation -0.02 0 0.1
      rotation 0 1 0 -1.87
      children [
        DEF sensor Shape {
          appearance PBRAppearance {
            baseColor 1 0.4 1
          }
          geometry Box {
            size 0.01 0.01 0.01
          }
        }
      ]
      name "ds_right"
      boundingObject USE sensor
      physics Physics {
      }
    }
    Solid {
      translation 0 0.15 0
      rotation 0 1 0 1.5708
      children [
        Shape {
          appearance PBRAppearance {
            metalness 0
          }
          geometry Box {
            size 0.02 0.25 0.02
          }
        }
      ]
      name "solid(4)"
      recognitionColors [
        0 0 0
      ]
    }
    SliderJoint {
      jointParameters JointParameters {
        axis 0 1 0
      }
      device [
        LinearMotor {
          name "linear"
          maxPosition 0.2
        }
      ]
      endPoint Solid {
        translation 0.00499976 0.15 0.08
        rotation 0 1 0 1.5708
        children [
          Shape {
            appearance PBRAppearance {
              metalness 0
            }
            geometry Box {
              size 0.15 0.02 0.02
            }
          }
          HingeJoint {
            jointParameters HingeJointParameters {
              axis 0 1 0
              anchor -0.075 1 0
            }
            device [
              RotationalMotor {
                name "rm"
              }
            ]
            endPoint Solid {
              translation -0.08 0 -0.00025
              rotation -0.025009367762669262 -0.025009367762669262 0.9993743357962637 1.57
              children [
                Shape {
                  appearance PBRAppearance {
                  }
                  geometry Cylinder {
                    height 0.02
                    radius 0.01
                  }
                }
                Camera {
                  translation -3.39722e-07 0.00562158 0.00830166
                  rotation -0.6215122169596978 -0.6215152169607452 0.47690816648080103 -2.2515953071795867
                  name "cam"
                  recognitionColors [
                    1 1 0
                  ]
                  recognition Recognition {
                  }
                }
              ]
            }
          }
        ]
        name "solid(5)"
      }
    }
  ]
  boundingObject USE body
  physics Physics {
  }
  recognitionColors [
    1 1 0
  ]
  controller "my_controller_cpp"
  linearVelocity -1.0896238350053751e-13 8.893916466020783e-10 1.888873060454941e-15
  angularVelocity 2.859254884803858e-14 6.230517200459644e-13 1.7510005415236476e-12
}
TexturedBackground {
}
TexturedBackgroundLight {
}
RectangleArena {
  translation 0 -0.03 0
  floorSize 2 2
  wallThickness 0.02
}
WoodenBox {
  hidden linearVelocity_0 -1.3101178711255149e-17 -8.106885748418329e-05 1.4757458335091883e-17
  hidden angularVelocity_0 -1.3322676295501885e-16 -2.321138658553274e-17 1.33226762955019e-16
  translation 0.57 0.1296179514175857 -2.6370090281488577e-16
  rotation 3.409028422728054e-14 0.9653519737373605 0.26095127284874925 1.878797073193286e-16
  size 0.2 0.2 0.2
  mass 1
}
WoodenBox {
  hidden linearVelocity_0 1.7223587851648542e-17 -8.106885748424022e-05 5.059267960899551e-18
  hidden angularVelocity_0 2.6645352591003756e-16 1.9278686651916297e-17 4.930380657631324e-32
  translation -0.5648159672455846 0.1296179514175857 0.12587915755842452
  rotation -1.6339955221306354e-15 -1 4.01485799132046e-15 0.007365273736300565
  name "wooden box(1)"
  size 0.2 0.2 0.2
  mass 1
}
Solid {
  children [
    Solid {
      translation 0 0.475 0
      children [
        Shape {
          appearance PBRAppearance {
            baseColor 0.8039 0.6745 0.5764
            baseColorMap ImageTexture {
              url [
                "textures/varnished_pine/varnished_pine_base_color.jpg"
              ]
            }
            roughnessMap ImageTexture {
              url [
                "textures/varnished_pine/varnished_pine_roughness.jpg"
              ]
            }
            metalness 0
            normalMap ImageTexture {
              url [
                "textures/varnished_pine/varnished_pine_normal.jpg"
              ]
            }
            normalMapFactor 0.5
            occlusionMap ImageTexture {
              url [
                "textures/varnished_pine/varnished_pine_occlusion.jpg"
              ]
            }
          }
          geometry IndexedFaceSet {
            coord Coordinate {
              point [
                -0.2 0.025 0.1
                0.2 0.025 0.1
                0.2 0.025 -0.1
                -0.2 0.025 -0.1
                -0.2 -0.025 -0.1
                0.2 -0.025 -0.1
                0.2 -0.025 0.1
                -0.2 -0.025 0.1
                -0.2 -0.025 0.1
                0.2 -0.025 0.1
                0.2 0.025 0.1
                -0.2 0.025 0.1
                0.2 -0.025 -0.1
                -0.2 -0.025 -0.1
                -0.2 0.025 -0.1
                0.2 0.025 -0.1
                -0.2 -0.025 -0.1
                -0.2 -0.025 0.1
                -0.2 0.025 0.1
                -0.2 0.025 -0.1
                0.2 -0.025 0.1
                0.2 -0.025 -0.1
                0.2 0.025 -0.1
                0.2 0.025 0.1
              ]
            }
            texCoord TextureCoordinate {
              point [
                0 0
                1 0
                1 0.5
                0 0.5
                0 0
                1 0
                1 0.5
                0 0.5
                0 0
                1 0
                1 0.125
                0 0.125
                0 0
                1 0
                1 0.125
                0 0.125
                0 0
                0.5 0
                0.5 0.125
                0 0.125
                0 0
                0.5 0
                0.5 0.125
                0 0.125
              ]
            }
            coordIndex [
              0, 1, 2, 3, -1, 4, 5, 6, 7, -1, 8, 9, 10, 11, -1, 12, 13, 14, 15, -1, 16, 17, 18, 19, -1, 20, 21, 22, 23, -1
            ]
            creaseAngle 1.5
          }
        }
      ]
      name "top frame"
      model "box"
      boundingObject Box {
        size 0.4 0.05 0.2
      }
    }
    Solid {
      translation -0.225 0.25 0
      children [
        Shape {
          appearance PBRAppearance {
            baseColor 0.8039 0.6745 0.5764
            baseColorMap ImageTexture {
              url [
                "textures/varnished_pine/varnished_pine_base_color.jpg"
              ]
            }
            roughnessMap ImageTexture {
              url [
                "textures/varnished_pine/varnished_pine_roughness.jpg"
              ]
            }
            metalness 0
            normalMap ImageTexture {
              url [
                "textures/varnished_pine/varnished_pine_normal.jpg"
              ]
            }
            normalMapFactor 0.5
            occlusionMap ImageTexture {
              url [
                "textures/varnished_pine/varnished_pine_occlusion.jpg"
              ]
            }
          }
          geometry IndexedFaceSet {
            coord Coordinate {
              point [
                -0.025 0.25 0.1
                0.025 0.25 0.1
                0.025 0.25 -0.1
                -0.025 0.25 -0.1
                -0.025 -0.25 -0.1
                0.025 -0.25 -0.1
                0.025 -0.25 0.1
                -0.025 -0.25 0.1
                -0.025 -0.25 0.1
                0.025 -0.25 0.1
                0.025 0.25 0.1
                -0.025 0.25 0.1
                0.025 -0.25 -0.1
                -0.025 -0.25 -0.1
                -0.025 0.25 -0.1
                0.025 0.25 -0.1
                -0.025 -0.25 -0.1
                -0.025 -0.25 0.1
                -0.025 0.25 0.1
                -0.025 0.25 -0.1
                0.025 -0.25 0.1
                0.025 -0.25 -0.1
                0.025 0.25 -0.1
                0.025 0.25 0.1
              ]
            }
            texCoord TextureCoordinate {
              point [
                0 0
                0.1 0
                0.1 0.4
                0 0.4
                0 0
                0.1 0
                0.1 0.4
                0 0.4
                0 0
                0.1 0
                0.1 1
                0 1
                0 0
                0.1 0
                0.1 1
                0 1
                0 0
                0.4 0
                0.4 1
                0 1
                0 0
                0.4 0
                0.4 1
                0 1
              ]
            }
            coordIndex [
              0, 1, 2, 3, -1, 4, 5, 6, 7, -1, 8, 9, 10, 11, -1, 12, 13, 14, 15, -1, 16, 17, 18, 19, -1, 20, 21, 22, 23, -1
            ]
            creaseAngle 1.5
          }
        }
      ]
      name "left frame"
      model "box"
      boundingObject Box {
        size 0.05 0.5 0.2
      }
    }
    Solid {
      translation 0.225 0.25 0
      children [
        Shape {
          appearance PBRAppearance {
            baseColor 0.8039 0.6745 0.5764
            baseColorMap ImageTexture {
              url [
                "textures/varnished_pine/varnished_pine_base_color.jpg"
              ]
            }
            roughnessMap ImageTexture {
              url [
                "textures/varnished_pine/varnished_pine_roughness.jpg"
              ]
            }
            metalness 0
            normalMap ImageTexture {
              url [
                "textures/varnished_pine/varnished_pine_normal.jpg"
              ]
            }
            normalMapFactor 0.5
            occlusionMap ImageTexture {
              url [
                "textures/varnished_pine/varnished_pine_occlusion.jpg"
              ]
            }
          }
          geometry IndexedFaceSet {
            coord Coordinate {
              point [
                -0.025 0.25 0.1
                0.025 0.25 0.1
                0.025 0.25 -0.1
                -0.025 0.25 -0.1
                -0.025 -0.25 -0.1
                0.025 -0.25 -0.1
                0.025 -0.25 0.1
                -0.025 -0.25 0.1
                -0.025 -0.25 0.1
                0.025 -0.25 0.1
                0.025 0.25 0.1
                -0.025 0.25 0.1
                0.025 -0.25 -0.1
                -0.025 -0.25 -0.1
                -0.025 0.25 -0.1
                0.025 0.25 -0.1
                -0.025 -0.25 -0.1
                -0.025 -0.25 0.1
                -0.025 0.25 0.1
                -0.025 0.25 -0.1
                0.025 -0.25 0.1
                0.025 -0.25 -0.1
                0.025 0.25 -0.1
                0.025 0.25 0.1
              ]
            }
            texCoord TextureCoordinate {
              point [
                0 0
                0.1 0
                0.1 0.4
                0 0.4
                0 0
                0.1 0
                0.1 0.4
                0 0.4
                0 0
                0.1 0
                0.1 1
                0 1
                0 0
                0.1 0
                0.1 1
                0 1
                0 0
                0.4 0
                0.4 1
                0 1
                0 0
                0.4 0
                0.4 1
                0 1
              ]
            }
            coordIndex [
              0, 1, 2, 3, -1, 4, 5, 6, 7, -1, 8, 9, 10, 11, -1, 12, 13, 14, 15, -1, 16, 17, 18, 19, -1, 20, 21, 22, 23, -1
            ]
            creaseAngle 1.5
          }
        }
      ]
      name "right frame"
      model "box"
      boundingObject Box {
        size 0.05 0.5 0.2
      }
    }
    HingeJoint {
      jointParameters HingeJointParameters {
        axis 0 1 0
        anchor -0.225 0.25 0.1
        minStop -1.57
        maxStop 0.01
        springConstant 5
        dampingConstant 10
      }
      endPoint Solid {
        translation 0 0 0.001
        children [
          Transform {
            translation 0 0.25 0.125
            rotation 0 1 0 -1.5708
            children [
              Shape {
                appearance PBRAppearance {
                  baseColorMap ImageTexture {
                    url [
                      "textures/door_base_color.jpg"
                    ]
                  }
                  roughness 0.25
                  metalness 0
                  normalMap ImageTexture {
                    url [
                      "textures/door_normal.jpg"
                    ]
                  }
                }
                geometry IndexedFaceSet {
                  coord Coordinate {
                    point [
                      -0.024999127613788 -0.2374999999984 -0.225
                      0.025000872386212 -0.2374999999984 -0.225
                      -0.025000872386212 0.2374999999984 -0.225
                      0.024999127613788 0.2374999999984 -0.225
                      -0.024999127613788 -0.2374999999984 0.225
                      0.025000872386212 -0.2374999999984 0.225
                      -0.025000872386212 0.2374999999984 0.225
                      0.024999127613788 0.2374999999984 0.225
                    ]
                  }
                  texCoord TextureCoordinate {
                    point [
                      0 0
                      1 0
                      0 1
                      1 1
                      0.001 0.001
                      1.001 0.001
                      0.001 1.001
                      1.001 1.001
                    ]
                  }
                  coordIndex [
                    1, 0, 2, 3, -1, 4, 5, 7, 6, -1, 5, 1, 3, 7, -1, 0, 4, 6, 2, -1, 7, 3, 2, 6, -1, 4, 0, 1, 5, -1
                  ]
                  texCoordIndex [
                    1, 5, 7, 3, -1, 0, 4, 6, 2, -1, 0, 1, 3, 2, -1, 1, 0, 2, 3, -1, 2, 3, 7, 6, -1, 0, 1, 5, 6, -1
                  ]
                }
              }
            ]
          }
          Transform {
            translation 0.2 0.25 0.125
            children [
              Slot {
                type "door handle"
                endPoint Slot {
                  type "door handle"
                  endPoint Solid {
                    children [
                      DEF HANDLE_SUPPORT Transform {
                        rotation 1 0 0 1.57
                        children [
                          Shape {
                            appearance PBRAppearance {
                              baseColorMap ImageTexture {
                                url [
                                  "textures/brushed_aluminium/brushed_aluminium_base_color.jpg"
                                ]
                              }
                              roughnessMap ImageTexture {
                                url [
                                  "textures/brushed_aluminium/brushed_aluminium_roughness.jpg"
                                ]
                              }
                              normalMap ImageTexture {
                                url [
                                  "textures/brushed_aluminium/brushed_aluminium_normal.jpg"
                                ]
                              }
                            }
                            geometry Cylinder {
                              height 0.075
                              radius 0.0375
                            }
                          }
                        ]
                      }
                      DEF HANDLE_AXIS Transform {
                        rotation 1 0 0 1.57
                        children [
                          Shape {
                            appearance PBRAppearance {
                              baseColorMap ImageTexture {
                                url [
                                  "textures/brushed_aluminium/brushed_aluminium_base_color.jpg"
                                ]
                              }
                              roughnessMap ImageTexture {
                                url [
                                  "textures/brushed_aluminium/brushed_aluminium_roughness.jpg"
                                ]
                              }
                              normalMap ImageTexture {
                                url [
                                  "textures/brushed_aluminium/brushed_aluminium_normal.jpg"
                                ]
                              }
                            }
                            geometry Capsule {
                              height 0.18
                              radius 0.0125
                            }
                          }
                        ]
                      }
                      DEF BACK_HANDLE Transform {
                        translation -0.06 0 -0.09
                        rotation 0 0 1 1.57
                        children [
                          Shape {
                            appearance PBRAppearance {
                              baseColorMap ImageTexture {
                                url [
                                  "textures/brushed_aluminium/brushed_aluminium_base_color.jpg"
                                ]
                              }
                              roughnessMap ImageTexture {
                                url [
                                  "textures/brushed_aluminium/brushed_aluminium_roughness.jpg"
                                ]
                              }
                              normalMap ImageTexture {
                                url [
                                  "textures/brushed_aluminium/brushed_aluminium_normal.jpg"
                                ]
                              }
                            }
                            geometry Capsule {
                              height 0.12
                              radius 0.0125
                            }
                          }
                        ]
                      }
                      DEF FRONT_HANDLE Transform {
                        translation -0.06 0 0.09
                        rotation 0 0 1 1.57
                        children [
                          Shape {
                            appearance PBRAppearance {
                              baseColorMap ImageTexture {
                                url [
                                  "textures/brushed_aluminium/brushed_aluminium_base_color.jpg"
                                ]
                              }
                              roughnessMap ImageTexture {
                                url [
                                  "textures/brushed_aluminium/brushed_aluminium_roughness.jpg"
                                ]
                              }
                              normalMap ImageTexture {
                                url [
                                  "textures/brushed_aluminium/brushed_aluminium_normal.jpg"
                                ]
                              }
                            }
                            geometry Capsule {
                              height 0.12
                              radius 0.0125
                            }
                          }
                        ]
                      }
                    ]
                    name "door lever"
                    model "door lever"
                    boundingObject Group {
                      children [
                        USE HANDLE_SUPPORT
                        USE HANDLE_AXIS
                        USE BACK_HANDLE
                        USE FRONT_HANDLE
                      ]
                    }
                    physics Physics {
                      density -1
                      mass 0.7
                    }
                  }
                }
              }
            ]
          }
          Transform {
            translation 0 0.25 0.125
          }
        ]
        boundingObject Transform {
          translation 0 0.25 0.125
          children [
            Box {
              size 0.45 0.475 0.05
            }
          ]
        }
        physics Physics {
          density 200
        }
      }
    }
  ]
  name "door"
  model "door"
  boundingObject Box {
    size 0.1 0.1 0.1
  }
  recognitionColors [
    1 1 0
  ]
}
